Workbook

Sheet DataIO2021
A1: INPUT - OUTPUT TABLE OF THAILAND 2021
A2: ROW | B2: ROW description | C2: COLUMN | D2: COLUMN description | E2: PURCHASER | F2: WHOLESALE | G2: RETAIL | H2: TRANSPORT | I2: IMPORT
A3: 001 | B3: =VLOOKUP(A3,'sector mapping'!A:B,2,0) | C3: 001 | D3: =VLOOKUP(C3,'sector mapping'!A:B,2,0) | E3: 23826912 | F3: 0 | G3: 0 | H3: 119524 | I3: 5
A4: 024 | B4: =VLOOKUP(A4,'sector mapping'!A:B,2,0) | C4: 001 | D4: =VLOOKUP(C4,'sector mapping'!A:B,2,0) | E4: 16110576 | F4: 0 | G4: 0 | H4: 0 | I4: 0
A5: 027 | B5: =VLOOKUP(A5,'sector mapping'!A:B,2,0) | C5: 001 | D5: =VLOOKUP(C5,'sector mapping'!A:B,2,0) | E5: 4505 | F5: 19 | G5: 63 | H5: 97 | I5: 0
A6: 071 | B6: =VLOOKUP(A6,'sector mapping'!A:B,2,0) | C6: 001 | D6: =VLOOKUP(C6,'sector mapping'!A:B,2,0) | E6: 728 | F6: 12 | G6: 0 | H6: 6 | I6: 0
A7: 074 | B7: =VLOOKUP(A7,'sector mapping'!A:B,2,0) | C7: 001 | D7: =VLOOKUP(C7,'sector mapping'!A:B,2,0) | E7: 29446 | F7: 3256 | G7: 507 | H7: 178 | I7: 0
A8: 078 | B8: =VLOOKUP(A8,'sector mapping'!A:B,2,0) | C8: 001 | D8: =VLOOKUP(C8,'sector mapping'!A:B,2,0) | E8: 5485 | F8: 684 | G8: 1020 | H8: 65 | I8: 0
A9: 085 | B9: =VLOOKUP(A9,'sector mapping'!A:B,2,0) | C9: 001 | D9: =VLOOKUP(C9,'sector mapping'!A:B,2,0) | E9: 43078118 | F9: 3655127 | G9: 2729612 | H9: 1325438 | I9: 24777541
A10: 088 | B10: =VLOOKUP(A10,'sector mapping'!A:B,2,0) | C10: 001 | D10: =VLOOKUP(C10,'sector mapping'!A:B,2,0) | E10: 32700 | F10: 2839 | G10: 3913 | H10: 208 | I10: 0
A11: 093 | B11: =VLOOKUP(A11,'sector mapping'!A:B,2,0) | C11: 001 | D11: =VLOOKUP(C11,'sector mapping'!A:B,2,0) | E11: 9834163 | F11: 376017 | G11: 350703 | H11: 88441 | I11: 1964873
A12: 094 | B12: =VLOOKUP(A12,'sector mapping'!A:B,2,0) | C12: 001 | D12: =VLOOKUP(C12,'sector mapping'!A:B,2,0) | E12: 256626 | F12: 24729 | G12: 12855 | H12: 4387 | I12: 0
A13: 097 | B13: =VLOOKUP(A13,'sector mapping'!A:B,2,0) | C13: 001 | D13: =VLOOKUP(C13,'sector mapping'!A:B,2,0) | E13: 8953 | F13: 1698 | G13: 1304 | H13: 236 | I13: 0
A14: 098 | B14: =VLOOKUP(A14,'sector mapping'!A:B,2,0) | C14: 001 | D14: =VLOOKUP(C14,'sector mapping'!A:B,2,0) | E14: 423548 | F14: 9127 | G14: 23654 | H14: 3032 | I14: 104099
... A12713: 190 | B12713: =VLOOKUP(A12713,'sector mapping'!A:B,2,0) | C12713: 700 | D12713: =VLOOKUP(C12713,'sector mapping'!A:B,2,0) | E12713: 46348019845 | F12713: 0 | G12713: 0 | H12713: 0 | I12713: 10046718641

Sheet sector mapping
A1: code | B1: IO sector | C1: Industry of the future
A2: 001 | B2: Paddy | C2: Agribusiness
A3: 002 | B3: Maize | C3: Agribusiness
A4: 003 | B4: Other cereals | C4: Agribusiness
A5: 004 | B5: Cassava | C5: Agribusiness
A6: 005 | B6: Other root crops | C6: Agribusiness
A7: 006 | B7: Beans and nuts | C7: Agribusiness
A8: 007 | B8: Vegetable | C8: Agribusiness
A9: 008 | B9: Fruits | C9: Agribusiness
A10: 009 | B10: Sugar cane | C10: Agribusiness
A11: 010 | B11: Coconut | C11: Agribusiness
A12: 011 | B12: Oil palm | C12: Agribusiness
... A30: 029 | B30: Inland fishing | C30: Agribusiness
A31: 030 | B31: Coal and lignite
A32: 031 | B32: Petroleum and natural gas
A33: 032 | B33: Iron ore
A34: 033 | B34: Tin ore
A35: 034 | B35: Tungsten ore
A36: 035 | B36: Other non-ferrous metals
A37: 036 | B37: Fluorite
A38: 037 | B38: Chemical fertilizers
A39: 038 | B39: Salt
A40: 039 | B40: Limestone
A41: 040 | B41: Stone quarrying
A42: 041 | B42: Other mining and quarrying
A43: 042 | B43: Slaughtering | C43: Agribusiness
A44: 043 | B44: Canning and preserving of meat | C44: Agribusiness
A45: 044 | B45: Dairy products | C45: Agribusiness
A46: 045 | B46: Canning and preservation of fruit and vegetables | C46: Agribusiness
A47: 046 | B47: Canning and preservation of fish and other sea foods | C47: Agribusiness
A48: 047 | B48: Coconut and palm oil | C48: Agribusiness
A49: 048 | B49: Animal oil, animal fat, vegetable oil and by-products | C49: Agribusiness
A50: 049 | B50: Rice milling | C50: Agribusiness
A51: 050 | B51: Tapioca milling | C51: Agribusiness
A52: 051 | B52: Grinding of maize | C52: Agribusiness
A53: 052 | B53: Flour and other grain milling | C53: Agribusiness
A54: 053 | B54: Bakery products | C54: Agribusiness
... A67: 066 | B67: Tobacco products | C67: Agribusiness
A68: 067 | B68: Spinning
A69: 068 | B69: Weaving
...
